<?xml version="1.0"?>
<robot name="tmy_robot" xmlns:xacro="http://ros.org/wiki/xacro">
 
  <xacro:property name="body_length" value="0.30"/>
  <xacro:property name="body_width" value="0.20"/>
  <xacro:property name="body_height" value="0.10"/>
     
  <xacro:property name="wheel_radius" value="0.075"/>
  <xacro:property name="wheel_width" value="0.05"/>

  <xacro:property name="wheel_x_scale" value="0.1"/>
  <xacro:property name="wheel_y_scale" value="0.1"/>
  <xacro:property name="wheel_z_scale" value="0.05"/>

  <xacro:property name="mini_z_scale" value="0.01"/>
 
  <xacro:macro name="box_inertia" params="m w h d">
    <inertial>
      <origin xyz="0 0 0" rpy="${pi/2} 0 ${pi/2}"/>
      <mass value="${m}"/>
      <inertia ixx="${(m/12) * (h*h + d*d)}" ixy="0.0" ixz="0.0" iyy="${(m/12) * (w*w + d*d)}" iyz="0.0" izz="${(m/12) * (w*w + h*h)}"/>
    </inertial>
  </xacro:macro>
 
  <xacro:macro name="cylinder_inertia" params="m r h">
    <inertial>
      <origin xyz="0 0 0" rpy="${pi/2} 0 0" />
      <mass value="${m}"/>
      <inertia ixx="${(m/12) * (3*r*r + h*h)}" ixy = "0" ixz = "0" iyy="${(m/12) * (3*r*r + h*h)}" iyz = "0" izz="${(m/2) * (r*r)}"/>
    </inertial>
  </xacro:macro>
 
  <xacro:macro name="sphere_inertia" params="m r">
    <inertial>
      <mass value="${m}"/>
      <inertia ixx="${(2/5) * m * (r*r)}" ixy="0.0" ixz="0.0" iyy="${(2/5) * m * (r*r)}" iyz="0.0" izz="${(2/5) * m * (r*r)}"/>
    </inertial>
  </xacro:macro>

  <link name="base_link"/>

  <joint name="base_joint" type="fixed">
    <parent link="base_link"/>
    <child link="body_link"/>
    <origin xyz="0.0 0.0 ${wheel_radius+wheel_z_scale}" rpy="0 0 0"/>
  </joint>
   
  <link name="body_link">
    <visual>
      <origin xyz="0 0 0" rpy="0 0 0"/>
      <geometry>
        <box size="${body_length} ${body_width} ${body_height}"/>
      </geometry>
    </visual>
 
    <collision>
      <geometry>
        <box size="${body_length} ${body_width} ${body_height}"/>
      </geometry>
    </collision>
 
    <xacro:box_inertia m="15.0" w="${body_width}" d="${body_length}" h="${body_height}"/>
  </link>
 
  <gazebo reference="body_link">
    <material>Gazebo/Green</material>
  </gazebo>

  <xacro:macro name="wheel" params="wheel_name x_wheel y_wheel">
    <link name="${wheel_name}_link">
      <visual>
        <origin xyz="0 0 0" rpy="${pi/2} 0 0"/>
        <geometry>
            <cylinder radius="${wheel_radius}" length="${wheel_width}"/>
        </geometry>
      </visual>
 
      <collision>
        <origin xyz="0 0 0" rpy="${pi/2} 0 0"/> 
        <geometry>
          <cylinder radius="${wheel_radius}" length="${wheel_width}"/>
        </geometry>
      </collision>
 
      <xacro:cylinder_inertia m="0.5" r="${wheel_radius}" h="${wheel_width}"/>
    </link>

    <joint name="${wheel_name}_joint" type="continuous">
      <parent link="body_link"/>
      <child link="${wheel_name}_link"/>
      <origin xyz="${x_wheel*wheel_x_scale} ${y_wheel*(wheel_y_scale+wheel_width/2)} ${-wheel_z_scale}" rpy="0 0 0"/>
      <axis xyz="0 1 0"/>
    </joint>

    <gazebo reference="${wheel_name}_link">
      <material>Gazebo/Cyan</material>
    </gazebo>
  </xacro:macro>

  <xacro:wheel wheel_name="lf_wheel" x_wheel="1" y_wheel="1" />
  <xacro:wheel wheel_name="lr_wheel" x_wheel="-1" y_wheel="1" />
  <xacro:wheel wheel_name="rf_wheel" x_wheel="1" y_wheel="-1" />
  <xacro:wheel wheel_name="rr_wheel" x_wheel="-1" y_wheel="-1" />

  <xacro:macro name="d_wheel" params="d_wheel_name y_d_wheel">
    <link name="${d_wheel_name}_d_link">
      <visual>
        <origin xyz="0 0 0" rpy="${pi/2} 0 0"/>
        <geometry>
          <box size="0.05 0.05 ${mini_z_scale}"/>
        </geometry>
      </visual>
 
      <collision>
        <origin xyz="0 0 0" rpy="${pi/2} 0 0"/> 
        <geometry>
          <box size="0.05 0.05 ${mini_z_scale}"/>
        </geometry>
      </collision>
    </link>

    <joint name="${d_wheel_name}_d_joint" type="fixed">
      <parent link="${d_wheel_name}_link"/>
      <child link="${d_wheel_name}_d_link"/>
      <origin xyz="0 ${y_d_wheel*((mini_z_scale+wheel_width)/2)} 0" rpy="0 0 0"/>
    </joint>

    <gazebo reference="${d_wheel_name}_d_link">
      <material>Gazebo/Green</material>
    </gazebo>
  </xacro:macro>

  <xacro:d_wheel d_wheel_name="lf_wheel" y_d_wheel="1" />
  <xacro:d_wheel d_wheel_name="lr_wheel" y_d_wheel="1" />
  <xacro:d_wheel d_wheel_name="rf_wheel" y_d_wheel="-1" />
  <xacro:d_wheel d_wheel_name="rr_wheel" y_d_wheel="-1" />

  <xacro:macro name="h_light" params="h_light_name y_h_light">
    <link name="${h_light_name}_link">
      <visual>
        <origin xyz="0 0 0" rpy="0 ${pi/2} 0"/>
        <geometry>
          <cylinder radius="0.025" length="0.01"/>
        </geometry>
      </visual>
 
      <collision>
        <origin xyz="0 0 0" rpy="0 ${pi/2} 0"/>
        <geometry>
          <cylinder radius="0.025" length="0.01"/>
        </geometry>
      </collision>
    </link>

    <joint name="${h_light_name}_joint" type="fixed">
      <parent link="body_link"/>
      <child link="${h_light_name}_link"/>
      <origin xyz="${(mini_z_scale+body_length)/2} ${y_h_light*(body_width/4)} ${body_height/2}" rpy="0 0 0"/>
    </joint>

    <gazebo reference="${h_light_name}_link">
      <material>Gazebo/Yellow</material>
    </gazebo>
  </xacro:macro>

  <xacro:h_light h_light_name="lh_light" y_h_light="1" />
  <xacro:h_light h_light_name="rh_light" y_h_light="-1" />


  <joint name="head_joint" type="fixed">
    <parent link="body_link"/>
    <child link="head_link"/>
    <origin xyz="0.1 0 0.06" rpy="0 0 0"/>
  </joint>

  <link name="head_link">
    <visual>
      <geometry>
        <box size="0.05 0.05 0.02"/>
      </geometry>
      <origin xyz="0 0 0" rpy="0 0 0"/>
    </visual>
    <collision>
      <geometry>
        <box size="0.05 0.05 0.02"/>
      </geometry>
      <origin xyz="0 0 0" rpy="0 0 0"/>
    </collision>
  </link>
  <gazebo reference="head_link">
    <material>Gazebo/Red</material>
  </gazebo>

  <joint name="de_lidar_joint" type="fixed">
    <parent link="body_link"/>
    <child link="de_lidar_link"/>
    <origin xyz="0 0 0.06" rpy="0 0 0"/>
  </joint>

  <link name="de_lidar_link">
    <visual>
      <geometry>
        <box size="0.15 0.15 0.02"/>
      </geometry>
      <origin xyz="0 0 0" rpy="0 0 0"/>
    </visual>
    <collision>
      <geometry>
        <box size="0.15 0.15 0.02"/>
      </geometry>
      <origin xyz="0 0 0" rpy="0 0 0"/>
    </collision>
    <inertial>
      <origin xyz="0 0 0" rpy="0 0 0"/>
      <mass value="0.125"/>
      <inertia ixx="0.001"  ixy="0"  ixz="0" iyy="0.001" iyz="0" izz="0.001" />
    </inertial>
  </link>
  <gazebo reference="de_lidar_link">
    <material>Gazebo/Blue</material>
  </gazebo>

  <joint name="lidar_joint" type="fixed">
    <parent link="de_lidar_link"/>
    <child link="lidar_link"/>
    <origin xyz="0 0 0.035" rpy="0 0 0"/>
  </joint>

  <link name="lidar_link">
    <visual>
      <origin xyz="0 0 0" rpy="0 0 0"/>
      <geometry>
        <cylinder radius="0.05" length="0.05"/>
      </geometry>
    </visual>
    <collision>
      <origin xyz="0 0 0" rpy="0 0 0"/>
      <geometry>
         <cylinder radius="0.05" length="0.05"/>
      </geometry>
    </collision>
    <inertial>
      <origin xyz="0 0 0" rpy="0 0 0"/>
      <mass value="0.125"/>
      <inertia ixx="0.001"  ixy="0"  ixz="0" iyy="0.001" iyz="0" izz="0.001" />
    </inertial>
  </link>
  <gazebo reference="lidar_link">
    <mu1>0.01</mu1>
    <mu2>0.01</mu2>
    <material>Gazebo/White</material>
  </gazebo>
     
  <gazebo reference="lidar_link">
    <sensor name="lidar" type="ray">
      <always_on>true</always_on>
      <visualize>true</visualize>
      <update_rate>30</update_rate>
      <ray>
        <scan>
          <horizontal>
            <samples>11</samples>
            <resolution>1.000000</resolution>
            <min_angle>3.14159</min_angle>
            <max_angle>-3.14159</max_angle>
          </horizontal>
        </scan>
        <range>
          <min>0.3</min>
          <max>10.0</max>
          <resolution>0.015</resolution>
        </range>
        <noise>
          <type>gaussian</type>
          <mean>0.0</mean>
          <stddev>0.01</stddev>
        </noise>
      </ray>
      <plugin name="scan" filename="libgazebo_ros_ray_sensor.so">
        <ros>
          <remapping>~/out:=scan</remapping>
        </ros>
        <output_type>sensor_msgs/LaserScan</output_type>
        <frame_name>lidar_link</frame_name>
      </plugin>
    </sensor>
  </gazebo>

  <gazebo>
    <plugin name="four_wheeled_robot_diff_drive" filename="libgazebo_ros_diff_drive.so">
      <update_rate>30</update_rate>

      <num_wheel_pairs>2</num_wheel_pairs>
      <left_joint>lf_wheel_joint</left_joint>
      <left_joint>lr_wheel_joint</left_joint>
      <right_joint>rf_wheel_joint</right_joint>
      <right_joint>rr_wheel_joint</right_joint>

      <wheel_separation>0.25</wheel_separation>
      <wheel_separation>0.25</wheel_separation>
      <wheel_diameter>0.15</wheel_diameter>
      <wheel_diameter>0.15</wheel_diameter>

      <max_wheel_torque>20</max_wheel_torque>
      <max_wheel_acceleration>1.0</max_wheel_acceleration>
  
      <command_topic>cmd_vel</command_topic>        
      <publish_odom>true</publish_odom>         
      <publish_odom_tf>false</publish_odom_tf>
      <publish_wheel_tf>true</publish_wheel_tf>
  
      <odometry_topic>odom</odometry_topic>
      <odometry_frame>odom</odometry_frame>
      <robot_base_frame>body_link</robot_base_frame>
  
      <odometry_source>1</odometry_source>
      <ros>
          <remapping>odom:=wheel/odometry</remapping>
      </ros>
    </plugin>
  </gazebo>

</robot>
