<?xml version="1.0"?>
<robot name="ttvn_robot">

    <material name="grey">
        <color rgba="0.6 0.6 0.6 1"/>
    </material>

    <material name="green">
        <color rgba="0 0.6 0 1"/>
    </material>

    <material name="red">
        <color rgba="1 0 0 1"/>
    </material>

    <material name="blue">
        <color rgba="0 0 1 1"/>
    </material>

    <material name="yellow">
        <color rgba="1 1 0 1"/>
    </material>

    <material name="white">
        <color rgba="1 1 1 1"/>
    </material>
    
    <link name="base_link"/>

    <link name="body_link">
        <visual>
            <geometry>
                <box size="0.3 0.2 0.1"/>
            </geometry>
            <origin xyz="0 0 0.05" rpy="0 0 0"/>
            <material name="green"/>
        </visual>
        <collision>
            <geometry>
                <box size="0.3 0.2 0.1"/>
            </geometry>
            <origin xyz="0 0 0.05" rpy="0 0 0"/>
        </collision>
        <inertial>
            <mass value="2.0"/>
            <origin xyz="0 0 0.05"/>
            <inertia ixx="0.01" ixy="0.0" ixz="0.0" iyy="0.01" iyz="0.0" izz="0.02"/>
        </inertial>
    </link>

    <link name="lf_wheel_link">
        <visual>
            <geometry>
                <cylinder radius="0.075" length="0.05"/>
            </geometry>
            <origin xyz="0 0 0" rpy="1.57 0 0"/>
            <material name="grey"/>
        </visual>
        <collision>
            <geometry>
                <cylinder radius="0.075" length="0.05"/>
            </geometry>
            <origin xyz="0 0 0" rpy="1.57 0 0"/>
        </collision>
        <inertial>
            <mass value="0.5"/>
            <origin xyz="0 0 0"/>
            <inertia ixx="0.001" ixy="0.0" ixz="0.0" iyy="0.001" iyz="0.0" izz="0.002"/>
        </inertial>
    </link>

    <link name="lr_wheel_link">
        <visual>
            <geometry>
                <cylinder radius="0.075" length="0.05"/>
            </geometry>
            <origin xyz="0 0 0" rpy="1.57 0 0"/>
            <material name="grey"/>
        </visual>
        <collision>
            <geometry>
                <cylinder radius="0.075" length="0.05"/>
            </geometry>
            <origin xyz="0 0 0" rpy="1.57 0 0"/>
        </collision>
        <inertial>
            <mass value="0.5"/>
            <origin xyz="0 0 0"/>
            <inertia ixx="0.001" ixy="0.0" ixz="0.0" iyy="0.001" iyz="0.0" izz="0.002"/>
        </inertial>
    </link>

    <link name="rf_wheel_link">
        <visual>
            <geometry>
                <cylinder radius="0.075" length="0.05"/>
            </geometry>
            <origin xyz="0 0 0" rpy="1.57 0 0"/>
            <material name="grey"/>
        </visual>
        <collision>
            <geometry>
                <cylinder radius="0.075" length="0.05"/>
            </geometry>
            <origin xyz="0 0 0" rpy="1.57 0 0"/>
        </collision>
        <inertial>
            <mass value="0.5"/>
            <origin xyz="0 0 0"/>
            <inertia ixx="0.001" ixy="0.0" ixz="0.0" iyy="0.001" iyz="0.0" izz="0.002"/>
        </inertial>
    </link>

    <link name="rr_wheel_link">
        <visual>
            <geometry>
                <cylinder radius="0.075" length="0.05"/>
            </geometry>
            <origin xyz="0 0 0" rpy="1.57 0 0"/>
            <material name="grey"/>
        </visual>
        <collision>
            <geometry>
                <cylinder radius="0.075" length="0.05"/>
            </geometry>
            <origin xyz="0 0 0" rpy="1.57 0 0"/>
        </collision>
        <inertial>
            <mass value="0.5"/>
            <origin xyz="0 0 0"/>
            <inertia ixx="0.001" ixy="0.0" ixz="0.0" iyy="0.001" iyz="0.0" izz="0.002"/>
        </inertial>
    </link>

    <link name="lfw_link">
        <visual>
            <geometry>
                <box size="0.05 0.05 0.01"/>
            </geometry>
            <origin xyz="0 0 0" rpy="1.57 0 0"/>
            <material name="green"/>
        </visual>
        <collision>
            <geometry>
                <box size="0.05 0.05 0.01"/>
            </geometry>
            <origin xyz="0 0 0" rpy="1.57 0 0"/>
        </collision>
    </link>

    <link name="lrw_link">
        <visual>
            <geometry>
                <box size="0.05 0.05 0.01"/>
            </geometry>
            <origin xyz="0 0 0" rpy="1.57 0 0"/>
            <material name="green"/>
        </visual>
        <collision>
            <geometry>
                <box size="0.05 0.05 0.01"/>
            </geometry>
            <origin xyz="0 0 0" rpy="1.57 0 0"/>
        </collision>
    </link>

    <link name="rfw_link">
        <visual>
            <geometry>
                <box size="0.05 0.05 0.01"/>
            </geometry>
            <origin xyz="0 0 0" rpy="1.57 0 0"/>
            <material name="green"/>
        </visual>
        <collision>
            <geometry>
                <box size="0.05 0.05 0.01"/>
            </geometry>
            <origin xyz="0 0 0" rpy="1.57 0 0"/>
        </collision>
    </link>

    <link name="rrw_link">
        <visual>
            <geometry>
                <box size="0.05 0.05 0.01"/>
            </geometry>
            <origin xyz="0 0 0" rpy="1.57 0 0"/>
            <material name="green"/>
        </visual>
        <collision>
            <geometry>
                <box size="0.05 0.05 0.01"/>
            </geometry>
            <origin xyz="0 0 0" rpy="1.57 0 0"/>
        </collision>
    </link>

    <link name="l_light_link">
        <visual>
            <geometry>
                <cylinder radius="0.025" length="0.01"/>
            </geometry>
            <origin xyz="0 0 0" rpy="0 1.57 0"/>
            <material name="yellow"/>
        </visual>
        <collision>
            <geometry>
                <cylinder radius="0.01" length="0.01"/>
            </geometry>
            <origin xyz="0 0 0" rpy="0 1.57 0"/>
        </collision>
    </link>

    <link name="r_light_link">
        <visual>
            <geometry>
                <cylinder radius="0.025" length="0.01"/>
            </geometry>
            <origin xyz="0 0 0" rpy="0 1.57 0"/>
            <material name="yellow"/>
        </visual>
        <collision>
            <geometry>
                <cylinder radius="0.01" length="0.01"/>
            </geometry>
            <origin xyz="0 0 0" rpy="0 1.57 0"/>
        </collision>
    </link>

    <link name="head_link">
        <visual>
            <geometry>
                <box size="0.05 0.05 0.02"/>
            </geometry>
            <origin xyz="0 0 0" rpy="0 0 0"/>
            <material name="red"/>
        </visual>
        <collision>
            <geometry>
                <box size="0.05 0.05 0.02"/>
            </geometry>
            <origin xyz="0 0 0" rpy="0 0 0"/>
        </collision>
    </link>

    <link name="de_lidar_link">
        <visual>
            <geometry>
                <box size="0.15 0.15 0.02"/>
            </geometry>
            <origin xyz="0 0 0" rpy="0 0 0"/>
            <material name="blue"/>
        </visual>
        <collision>
            <geometry>
                <box size="0.15 0.15 0.02"/>
            </geometry>
            <origin xyz="0 0 0" rpy="0 0 0"/>
        </collision>
    </link>

    <link name="lidar_link">
        <visual>
            <geometry>
                <cylinder radius="0.05" length="0.05"/>
            </geometry>
            <origin xyz="0 0 0" rpy="0 0 0"/>
            <material name="white"/>
        </visual>
        <collision>
            <geometry>
                <cylinder radius="0.05" length="0.05"/>
            </geometry>
            <origin xyz="0 0 0" rpy="0 0 0"/>
        </collision>
        <inertial>
            <origin xyz="0 0 0" rpy="0 0 0"/>
            <mass value="0.125"/>
            <inertia ixx="0.001" ixy="0" ixz="0" iyy="0.001" iyz="0" izz="0.001"/>
        </inertial>
    </link>

    <joint name="base_joint" type="fixed">
        <parent link="base_link"/>
        <child link="body_link"/>
        <origin xyz="0 0 0.075" rpy="0 0 0" />
    </joint>

    <joint name="base_lf_wheel_joint" type="continuous">
        <parent link="body_link"/>
        <child link="lf_wheel_link"/>
        <origin xyz="0.1 0.125 0" rpy="0 0 0"/>
        <axis xyz="0 1 0"/>
        <dynamics damping="0.1" friction="0.5"/>
    </joint>

    <joint name="base_lr_wheel_joint" type="continuous">
        <parent link="body_link"/>
        <child link="lr_wheel_link"/>
        <origin xyz="-0.1 0.125 0" rpy="0 0 0"/>
        <axis xyz="0 1 0"/>
        <dynamics damping="0.1" friction="0.5"/>
    </joint>

    <joint name="base_rf_wheel_joint" type="continuous">
        <parent link="body_link"/>
        <child link="rf_wheel_link"/>
        <origin xyz="0.1 -0.125 0" rpy="0 0 0"/>
        <axis xyz="0 1 0"/>
        <dynamics damping="0.1" friction="0.5"/>
    </joint>

    <joint name="base_rr_wheel_joint" type="continuous">
        <parent link="body_link"/>
        <child link="rr_wheel_link"/>
        <origin xyz="-0.1 -0.125 0" rpy="0 0 0"/>
        <axis xyz="0 1 0"/>
        <dynamics damping="0.1" friction="0.5"/>
    </joint>

    <joint name="lfw_joint" type="fixed">
        <parent link="lf_wheel_link"/>
        <child link="lfw_link"/>
        <origin xyz="0 0.03 0" rpy="0 0 0"/>
    </joint>

    <joint name="lrw_joint" type="fixed">
        <parent link="lr_wheel_link"/>
        <child link="lrw_link"/>
        <origin xyz="0 0.03 0" rpy="0 0 0"/>
    </joint>

    <joint name="rfw_joint" type="fixed">
        <parent link="rf_wheel_link"/>
        <child link="rfw_link"/>
        <origin xyz="0 -0.03 0" rpy="0 0 0"/>
    </joint>

    <joint name="rrw_joint" type="fixed">
        <parent link="rr_wheel_link"/>
        <child link="rrw_link"/>
        <origin xyz="0 -0.03 0" rpy="0 0 0"/>
    </joint>

    <joint name="llight_joint" type="fixed">
        <parent link="body_link"/>
        <child link="l_light_link"/>
        <origin xyz="0.15 -0.05 0.05" rpy="0 0 0"/>
    </joint>

    <joint name="rlight_joint" type="fixed">
        <parent link="body_link"/>
        <child link="r_light_link"/>
        <origin xyz="0.15 0.05 0.05" rpy="0 0 0"/>
    </joint>

    <joint name="head_joint" type="fixed">
        <parent link="body_link"/>
        <child link="head_link"/>
        <origin xyz="0.1 0 0.11" rpy="0 0 0"/>
    </joint>

    <joint name="de_lidar_joint" type="fixed">
        <parent link="body_link"/>
        <child link="de_lidar_link"/>
        <origin xyz="0 0 0.11" rpy="0 0 0"/>
    </joint>

    <joint name="lidar_joint" type="fixed">
        <parent link="de_lidar_link"/>
        <child link="lidar_link"/>
        <origin xyz="0 0 0.035" rpy="0 0 0"/>
    </joint>

    <gazebo reference="lidar_link">
        <mu1>0.01</mu1>
        <mu2>0.01</mu2>
        <material>Gazebo/White</material>
    </gazebo>
        
    <gazebo reference="lidar_link">
        <sensor name="lidar" type="ray">
        <always_on>true</always_on>
        <visualize>true</visualize>
        <update_rate>20</update_rate>
        <ray>
            <scan>
            <horizontal>
                <samples>11</samples>
                <resolution>1.000000</resolution>
                <min_angle>3.14159</min_angle>
                <max_angle>-3.14159</max_angle>
            </horizontal>
            </scan>
            <range>
            <min>0.3</min>
            <max>10.0</max>
            <resolution>0.015</resolution>
            </range>
            <noise>
            <type>gaussian</type>
            <mean>0.0</mean>
            <stddev>0.01</stddev>
            </noise>
        </ray>
        <plugin name="scan" filename="libgazebo_ros_ray_sensor.so">
            <ros>
            <remapping>~/out:=scan</remapping>
            </ros>
            <output_type>sensor_msgs/LaserScan</output_type>
            <frame_name>lidar_link</frame_name>
        </plugin>
        </sensor>
    </gazebo>

    <gazebo>
        <plugin name="four_wheeled_robot_diff_drive" filename="libgazebo_ros_diff_drive.so">
        <update_rate>20</update_rate>

        <num_wheel_pairs>2</num_wheel_pairs>
        <left_joint>lf_wheel_joint</left_joint>
        <left_joint>lr_wheel_joint</left_joint>
        <right_joint>rf_wheel_joint</right_joint>
        <right_joint>rr_wheel_joint</right_joint>

        <wheel_separation>0.25</wheel_separation>
        <wheel_separation>0.25</wheel_separation>
        <wheel_diameter>0.15</wheel_diameter>
        <wheel_diameter>0.15</wheel_diameter>

        <max_wheel_torque>20</max_wheel_torque>
        <max_wheel_acceleration>1.0</max_wheel_acceleration>
    
        <command_topic>cmd_vel</command_topic>        
        <publish_odom>true</publish_odom>         
        <publish_odom_tf>false</publish_odom_tf>
        <publish_wheel_tf>true</publish_wheel_tf>
    
        <odometry_topic>odom</odometry_topic>
        <odometry_frame>odom</odometry_frame>
        <robot_base_frame>body_link</robot_base_frame>
    
        <odometry_source>1</odometry_source>
        <ros>
            <remapping>odom:=wheel/odometry</remapping>
        </ros>
        </plugin>
    </gazebo>
    
</robot>
