<?xml version="1.0"?>
<robot name="ttvn_robot" xmlns:xacro="http://www.ros.org/wiki/xacro">

    <xacro:property name="body_link_x_dim" value="0.3" />
    <xacro:property name="body_link_y_dim" value="0.2" />
    <xacro:property name="body_link_z_dim" value="0.1" />

    <xacro:property name="wheel_link_radius" value="0.075" />
    <xacro:property name="wheel_link_length" value="0.05" />
    <xacro:property name="wheel_link_z_location" value="-0.05" />

    <xacro:property name="body_density" value="2700.0" />
    <xacro:property name="wheel_density" value="2700.0" />

    <xacro:property name="pi_const" value="3.14159265" />

    <xacro:property name="body_mass" value="${body_density*body_link_x_dim*body_link_y_dim*body_link_z_dim}" />
    <xacro:property name="wheel_mass" value="${wheel_density*pi_const*wheel_link_radius*wheel_link_length}" />

    <xacro:property name="Iz_wheel" value="${0.5*wheel_mass*wheel_link_radius*wheel_link_radius}" />
    <xacro:property name="I_wheel" value="${(1.0/12.0)*wheel_mass*(3.0*wheel_link_radius*wheel_link_radius+wheel_link_length*wheel_link_length)}" />

    <xacro:macro name="inertia_wheel">
        <inertia>
        <origin xyz="0 0 0" rpy="0 0 0" />
        <mass value="${wheel_mass}" />
        <inertia ixx="${I_wheel}" ixy="0.0" ixz="0.0" iyy="${I_wheel}" iyz="0.0" izz="${Iz_wheel}" />
        </inertia>
    </xacro:macro>

    <!-- <xacro:include filename="$(find ttvn_pkg)/urdf/ttvn_robot.gazebo"/> -->
    <material name="gray">
        <color rgba="0.6 0.6 0.6 1"/>
    </material>

    <material name="green">
        <color rgba="0 0.6 0 1"/>
    </material>

    <material name="red">
        <color rgba="1 0 0 1"/>
    </material>

    <material name="blue">
        <color rgba="0 0 1 1"/>
    </material>

    <material name="yellow">
        <color rgba="1 1 0 1"/>
    </material>

    <material name="white">
        <color rgba="1 1 1 1"/>
    </material>

    <link name="base_link"/>

    <joint name="base_joint" type="fixed">
        <parent link="base_link"/>
        <child link="body_link"/>
        <origin xyz="0 0 0.075" rpy="0 0 0" />
    </joint>

    <link name="body_link">
        <visual>
            <geometry>
                <box size="${body_link_x_dim} ${body_link_y_dim} ${body_link_z_dim}" />
            </geometry>
            <origin xyz="0 0 0" rpy="0 0 0" />
            <material name="green"/>
        </visual>
        <collision>
            <geometry>
                <box size="${body_link_x_dim} ${body_link_y_dim} ${body_link_z_dim}" />
            </geometry>
            <origin xyz="0 0 0" rpy="0 0 0" />
        </collision>
        <inertial>
            <origin xyz="0 0 0" rpy="0 0 0" />
            <mass value="${body_mass}" />
            <inertia 
            ixx="${(1.0/12.0)*body_mass*(body_link_y_dim*body_link_y_dim+body_link_z_dim*body_link_z_dim)}"
            ixy="0"
            ixz="0"
            iyy="${(1.0/12.0)*body_mass*(body_link_x_dim*body_link_x_dim+body_link_z_dim*body_link_z_dim)}"
            iyz="0"
            izz="${(1.0/12.0)*body_mass*(body_link_y_dim*body_link_y_dim+body_link_x_dim*body_link_x_dim)}"
            />
        </inertial>
    </link>

    <joint name="fl_wheel_joint" type="continuous">
        <parent link="body_link"/>
        <child link="fl_wheel_link"/>
        <origin xyz="${body_link_x_dim/2-0.05} ${body_link_y_dim/2+wheel_link_length/2} ${wheel_link_z_location}" rpy="0 0 0" />
        <axis xyz="0 1 0"/>
        <limit effort="1000" velocity="1000"/>
        <dynamics damping="1.0" friction="1.0"/>
    </joint>

    <link name="fl_wheel_link">
        <visual>
            <geometry>
                <cylinder length="${wheel_link_length}" radius="${wheel_link_radius}"/>
            </geometry>
            <origin xyz="0 0 0" rpy="1.57 0 0" />
            <material name="gray"/>
        </visual>
        <collision>
            <geometry>
                <cylinder length="${wheel_link_length}" radius="${wheel_link_radius}"/>
            </geometry>
            <origin xyz="0 0 0" rpy="1.57 0 0" />
        </collision>
        <xacro:inertia_wheel />
    </link>

    <joint name="rl_wheel_joint" type="continuous">
        <parent link="body_link"/>
        <child link="rl_wheel_link"/>
        <origin xyz="${-body_link_x_dim/2+0.05} ${body_link_y_dim/2+wheel_link_length/2} ${wheel_link_z_location}" rpy="0 0 0" />
        <axis xyz="0 1 0"/>
        <limit effort="1000" velocity="1000"/>
        <dynamics damping="1.0" friction="1.0" />
    </joint>

    <link name="rl_wheel_link">
        <visual>
            <geometry>
                <cylinder length="${wheel_link_length}" radius="${wheel_link_radius}"/>
            </geometry>
            <origin xyz="0 0 0" rpy="1.57 0 0" />
            <material name="gray"/>
        </visual>
        <collision>
            <geometry>
                <cylinder length="${wheel_link_length}" radius="${wheel_link_radius}"/>
            </geometry>
            <origin xyz="0 0 0" rpy="1.57 0 0" />
        </collision>
        <xacro:inertia_wheel />
    </link>

    <joint name="fr_wheel_joint" type="continuous">
        <parent link="body_link"/>
        <child link="fr_wheel_link"/>
        <origin xyz="${body_link_x_dim/2-0.05} ${-body_link_y_dim/2-wheel_link_length/2} ${wheel_link_z_location}" rpy="0 0 0" />
        <axis xyz="0 1 0"/>
        <limit effort="1000" velocity="1000"/>
        <dynamics damping="1.0" friction="1.0" />
    </joint>

    <link name="fr_wheel_link">
        <visual>
            <geometry>
                <cylinder length="${wheel_link_length}" radius="${wheel_link_radius}"/>
            </geometry>
            <origin xyz="0 0 0" rpy="1.57 0 0" />
            <material name="gray"/>
        </visual>
        <collision>
            <geometry>
                <cylinder length="${wheel_link_length}" radius="${wheel_link_radius}"/>
            </geometry>
            <origin xyz="0 0 0" rpy="1.57 0 0" />
        </collision>
        <xacro:inertia_wheel />
    </link>

    <joint name="rr_wheel_joint" type="continuous">
        <parent link="body_link"/>
        <child link="rr_wheel_link"/>
        <origin xyz="${-body_link_x_dim/2+0.05} ${-body_link_y_dim/2-wheel_link_length/2} ${wheel_link_z_location}" rpy="0 0 0" />
        <axis xyz="0 1 0"/>
        <limit effort="1000" velocity="1000"/>
        <dynamics damping="1.0" friction="1.0" />
    </joint>

    <link name="rr_wheel_link">
        <visual>
            <geometry>
                <cylinder length="${wheel_link_length}" radius="${wheel_link_radius}"/>
            </geometry>
            <origin xyz="0 0 0" rpy="1.57 0 0" />
            <material name="gray"/>
        </visual>
        <collision>
            <geometry>
                <cylinder length="${wheel_link_length}" radius="${wheel_link_radius}"/>
            </geometry>
            <origin xyz="0 0 0" rpy="1.57 0 0" />
        </collision>
        <xacro:inertia_wheel />
    </link>

    <gazebo>
        <plugin name="skid_steer_drive_controller" filename="libgazebo_ros_skid_steer_drive.so">
            <updateRate>100.0</updateRate>
            <robotNamespace> </robotNamespace>

            <leftFrontJoint>fl_wheel_joint</leftFrontJoint>
            <rightFrontJoint>fr_wheel_joint</rightFrontJoint>
            <leftRearJoint>rl_wheel_joint</leftRearJoint>
            <rightRearJoint>rr_wheel_joint</rightRearJoint>

            <wheelSeparation>${body_link_y_dim+wheel_link_length}</wheelSeparation>
            <wheelDiameter>${2*wheel_link_radius}</wheelDiameter>
            <torque>1000</torque>

            <robotBaseFrame>base_link</robotBaseFrame>
            <commandTopic>cmd_vel</commandTopic>
            <odometryTopic>odom</odometryTopic>
            <odometryFrame>odom</odometryFrame>
            <publishWheelTF>true</publishWheelTF>
            <publishOdom>true</publishOdom>
            <publishWheelJointState>true</publishWheelJointState>
            <covariance_x>0.0001</covariance_x>
            <covariance_y>0.0001</covariance_y>
            <covariance_yaw>0.01</covariance_yaw>
        </plugin>
    </gazebo>

</robot>
